Workbook

Sheet list
A1: REQUIRED DOCUMENTS
A3: APPLICANT'S | I3: M | J3: STUDENT（Graduated/Enrolled) | P3: JAPANESE SCHOOL | R3: Completed Enrolled
A4: NAME | I4: F | J4: EMPLOYED
A5: SPONSOR | C5: Father / Mother / Other( ) | J5: Employed / Executive / Self-employed / Other （ ）
A7: Mark "○" to the documents you have prepared.
A8: Mark "×" to the documents you can not or don't have to turn in.
A9: Mark "△" to the documents you intend to turn in later.
A10: If you have any documents other than listed below, please describe in the "OTHERS" colomn.
A12: DOCUMENTS | R12: Original/Copy | S12: Translation | T12: Remarks
A13: OBLIGATORY | B13: APPLICANT | C13: 1 | D13: 6 Photos （length 4cm×width 3ｃｍ. Name and Date of Birth be written on the back.） | S13: ×
C14: 2 | D14: Copy of Passport | S14: ×
C15: 3 | D15: Application Form | S15: ×
C16: 4 | D16: Reason for Studying Japanese in Japan
C17: 5 | D17: Graduate Diploma
C18: 6 | D18: Certificate of Enrollment or Certificate of Possible Graduate
C19: 7 | D19: VJEEC Credentials Report of the final academic record(Vietnam)
C20: 8 | D20: SLC Certificate(Nepal)
C21: 9 | D21: Certificate of Grade for the final education period
C22: 10 | D22: Examination Voucher of JLPT(N5 or over) or NAT (Level 5 or over) or J-Test (Level F or over) | S22: ×
C23: 11 | D23: Certificate of JLPT(N5 or over) or NAT (Level 5 or over) or J-Test (Level F or over) | S23: ×
C24: 12 | D24: Certificate of Employment
C25: 13 | D25: Certificate of Studying Japanese (More than 150 hours)
C26: 14 | D26: Certificate of Family Register
C27: 15 | D27: Copy of Identification by the Authority (Applicant) | S27: ×
B28: SPONSOR | C28: 16 | D28: Statement of Sponsorship
C29: 17 | D29: Certificate of Balance (VND or NRS or US$) | S29: ×
C30: 18 | D30: Color Copy of Passbook or Certificate of Bank Transaction (past 3 years) | S30: ×
C31: 19 | D31: Explanation of Fund Raising
C32: 20 | D32: Certificate of Employment
C33: 21 | D33: Certificate of Business Register (in case of a company executive)
C34: 22 | D34: Certificate of Business Owner (in case of self-employed or a company owner)
C35: 23 | D35: Copy of Land Rent or House Rent Contract (if renting lands or houses)
C36: 24 | D36: Copy of Land Owner or House Owner certificate (if renting lands or houses)
C37: 25 | D37: Certificate of Land Register (if farming)
C38: 26 | D38: Certificate of Taxation to testify annual income
C39: 27 | D39: Documents to testify annual income(If cannot be issued.)
C40: 28 | D40: Official Evidence of Family Structure
C41: 29 | D41: Certificate of Resident Registration (If seperated)
C42: 30 | D42: Copy of Identification by the Authority (Sponsor) | S42: ×
B44: OTHERS
...

Sheet reason
A1: REASON OF STUDYING JAPANESE IN JAPAN
A2: アジア学院 ASIAN ACADEMY | E2: DATE
E3: NAME
E4: SIGNATURE

Sheet app. form example
A1: APPLICATION FORM
A3: NAME | C3: SURNAME | J3: GIVEN NAME
A5: NATIONALITY | F5: DATE OF BIRTH | O5: GENDER | Q5: PHOTO
F6: (Y) | I6: /(M) | L6: /(D) | O6: MALE FEMALE
A7: HOME COUNTRY | C7: REGISTERED ADDRESS | Q7: 4cm × 3cm
C9: ACTUAL ADDRESS
C10: sam as above /
C11: HOME PHONE NUMBER / NONE | K11: MOBILE PHONE NUMBER
A14: SPONSOR AND FAMILY (Describe up to the second degree of kinship including "separated" or "divorced".
A15: NAME | D15: RELATION | F15: DATE OF BIRTH | I15: ADDRESS | Q15: OCCUPATION/REMARK
A16: SPONSOR | I16: REGISTERED ADDRESS
I17: ACTUAL ADDRESS / SAME AS ABOVE
I18: REGISTERED ADDRESS
I19: ACTUAL ADDRESS / SAME AS ABOVE
I20: REGISTERED ADDRESS
I21: ACTUAL ADDRESS / SAME AS ABOVE
I22: REGISTERED ADDRESS
I23: ACTUAL ADDRESS / SAME AS ABOVE
I24: REGISTERED ADDRESS
I25: ACTUAL ADDRESS / SAME AS ABOVE
A27: ACADEMIC RECORD (FROM PRIMARY SCHOOL TO THE FINAL RECORD)
C28: NAME OF SHOOL & ADDRESS | L28: DATE OF ADMISSION | O28: DATE OF GRADUATION | R28: PERIOD
A29: NAME | L29: (Y) /(M) /(D) | O29: (Y) /(M) /(D) | R29: YEARS
A30: ADDRESS
A31: NAME | L31: (Y) /(M) /(D) | O31: (Y) /(M) /(D) | R31: YEARS
A32: ADDRESS
A33: NAME | L33: (Y) /(M) /(D) | O33: (Y) /(M) /(D) | R33: YEARS
A34: ADDRESS
A35: NAME | L35: (Y) /(M) /(D) | O35: (Y) /(M) /(D) | R35: YEARS
A36: ADDRESS
A38: JOB CAREER | E38: NONE
A39: NAME | P39: TYPE OF JOB | R39: PERIOD
L40: (Y) /(M) /(D) ～ | R40: YEARS
A41: ADDRESS
L42: (Y) /(M) /(D)
A44: RECORD OF JAPANESE LANGUAGE LEARNING
A45: NAME | P45: PERIOD | R45: TOTAL HOURS
L46: (Y) /(M) /(D) ～ | P46: YEARS MONTHS | R46: HOURS
A47: ADDRESS
L48: (Y) /(M) /(D)
...

Sheet fee
A1: EXPENSES
A3: ◆College Preparatory 2 year Course (Starting in April) | N3: 2022.9.1
B4: fee | D4: The Initial Installment | H4: The Second Installment (the following March) | L4: GRAND TOTAL
B5: Admission Fee | D5: ￥ | E5: 50000 | H5: ￥ | I5: 0 | L5: ￥ | M5: =SUM(E10,I10) -> 1672000
B6: Examination Fee | D6: ￥ | E6: 30000 | I6: 0
B7: Tuition | D7: ￥ | E7: ='regular plan'!E7:G7 -> 660000 | H7: ￥ | I7: =E7 -> 660000
B8: Miscellaneous Fee | D8: ￥ | E8: ='regular plan'!E8:G8 -> 60000 | H8: ￥ | I8: =E8 -> 60000
B9: Consumption Tax(10%) | D9: ￥ | E9: =(E5+E6+E7+E8)*0.1 -> 80000 | H9: ￥ | I9: =(I5+I6+I7+I8)*0.1 -> 72000
B10: SUB TOTAL | D10: ￥ | E10: =SUM(E5:G9) -> 880000 | H10: ￥ | I10: =SUM(I5:K9) -> 792000
A13: ◆College Preparatory 1.9 year Course (Starting in July)
D14: The Initial Installment | H14: The Second Installment (the following June) | L14: GRAND TOTAL
B15: Admission Fee | D15: ￥ | E15: 50000 | H15: ￥ | I15: 0 | L15: ￥ | M15: =SUM(E20,I20) -> 1474000
B16: Examination Fee | D16: ￥ | E16: 30000 | H16: ￥ | I16: 0
B17: Tuition | D17: ￥ | E17: ='regular plan'!E17:G17 -> 660000 | H17: ￥ | I17: =E17/4*3 -> 495000
B18: Miscellaneous Fee | D18: ￥ | E18: ='regular plan'!E18:G18 -> 60000 | H18: ￥ | I18: =E18/4*3 -> 45000
B19: Consumption Tax(10%) | D19: ￥ | E19: =(E15+E16+E17+E18)*0.1 -> 80000 | H19: ￥ | I19: =(I17+I18)*0.1 -> 54000
B20: SUB TOTAL | D20: ￥ | E20: =SUM(E15:G19) -> 880000 | H20: ￥ | I20: =SUM(I15:K19) -> 594000
A23: ◆College Preparatory 1.5 year Course (Starting in October)
D24: The Initial Installment | H24: The Second Installment (the following September) | L24: GRAND TOTAL
B25: Admission Fee | D25: ￥ | E25: 50000 | H25: ￥ | I25: 0 | L25: ￥ | M25: =SUM(E30,I30) -> 1276000
B26: Examination Fee | D26: ￥ | E26: 30000 | H26: ￥ | I26: 0
B27: Tuition | D27: ￥ | E27: ='regular plan'!E27:G27 -> 660000 | H27: ￥ | I27: =E27/2 -> 330000
B28: Miscellaneous Fee | D28: ￥ | E28: ='regular plan'!E28:G28 -> 60000 | H28: ￥ | I28: =E28/2 -> 30000
B29: Consumption Tax(10%) | D29: ￥ | E29: =(E25+E26+E27+E28)*0.1 -> 80000 | H29: ￥ | I29: =(I27+I28)*0.1 -> 36000
B30: SUB TOTAL | D30: ￥ | E30: =SUM(E25:G29) -> 880000 | H30: ￥ | I30: =SUM(I25:K29) -> 396000
A33: ◆College Preparatory 1.3 year Course (Starting in January)
D34: The Initial Installment | H34: The Second Installment (the following December) | L34: GRAND TOTAL
B35: Admission Fee | D35: ￥ | E35: 50000 | H35: ￥ | I35: 0 | L35: ￥ | M35: =SUM(E40,I40) -> 1078000
B36: Examination Fee | D36: ￥ | E36: 30000 | H36: ￥ | I36: 0
B37: Tuition | D37: ￥ | E37: ='regular plan'!E37:G37 -> 660000 | H37: ￥ | I37: =E37/4 -> 165000
B38: Miscellaneous Fee | D38: ￥ | E38: ='regular plan'!E38:G38 -> 60000 | H38: ￥ | I38: =E38/4 -> 15000
B39: Consumption Tax(10%) | D39: ￥ | E39: =(E35+E36+E37+E38)*0.1 -> 80000 | H39: ￥ | I39: =(I37+I38)*0.1 -> 18000
B40: SUB TOTAL | D40: ￥ | E40: =SUM(E35:G39) -> 880000 | H40: ￥ | I40: =SUM(I35:K39) -> 198000
G42: ASIAN ACADEMY
N45: 2022.9.1
A48: THE INITIAL PAYMENT
B51: TUITION | D51: JPY 800,000
B52: CONSUMPTION TAX(10%) | D52: JPY 80,000
B53: INSURANCE FOR ACCIDENT | D53: JPY 10,000 | H53: ( 1 Year)
B55: BANK FEE | D55: JPY 5,000
...

Sheet regular plan
A1: EXPENSES
Q2: 2022.9.1
A3: ◆College Preparatory 2 year Course (Starting in April)
D4: On Admission | H4: March (2nd Year) | L4: September (2nd Year) | P4: GRAND TOTAL
B5: Admission Fee | D5: ￥ | E5: 50000 | P5: ￥ | Q5: =SUM(E10,I10,M10) -> 1672000
B6: Examination Fee | D6: ￥ | E6: 30000
B7: Tuition | D7: ￥ | E7: ='installment plan'!E7:G7*2 -> 660000 | H7: ￥ | I7: ='installment plan'!I7:K7 -> 330000 | L7: ￥ | M7: ='installment plan'!M7:O7 -> 330000
B8: Miscellaneous Fee | D8: ￥ | E8: ='installment plan'!E8:G8*2 -> 60000 | H8: ￥ | I8: ='installment plan'!I8:K8 -> 30000 | L8: ￥ | M8: ='installment plan'!M8:O8 -> 30000
B9: Consumption Tax(10%) | D9: ￥ | E9: =(E5+E6+E7+E8)*0.1 -> 80000 | H9: ￥ | I9: =(I7+I8)*0.1 -> 36000 | L9: ￥ | M9: =(M7+M8)*0.1 -> 36000
B10: SUB TOTAL | D10: ￥ | E10: =SUM(E5:G9) -> 880000 | H10: ￥ | I10: =SUM(I5:K9) -> 396000 | L10: ￥ | M10: =SUM(M5:O9) -> 396000
A13: ◆College Preparatory 1.9 year Course (Starting in July)
D14: On Admission | H14: June (2nd Year) | L14: December (2nd Year) | P14: GRAND TOTAL
B15: Admission Fee | D15: ￥ | E15: 50000 | P15: ￥ | Q15: =SUM(E20,I20,M20) -> 1474000
B16: Examination Fee | D16: ￥ | E16: 30000
B17: Tuition | D17: ￥ | E17: ='installment plan'!E17:G17*2 -> 660000 | H17: ￥ | I17: ='installment plan'!I17:K17 -> 330000 | L17: ￥ | M17: =I17/2 -> 165000
B18: Miscellaneous Fee | D18: ￥ | E18: ='installment plan'!E18:G18*2 -> 60000 | H18: ￥ | I18: ='installment plan'!I18:K18 -> 30000 | L18: ￥ | M18: =I18/2 -> 15000
B19: Consumption Tax(10%) | D19: ￥ | E19: =(E15+E16+E17+E18)*0.1 -> 80000 | H19: ￥ | I19: =(I17+I18)*0.1 -> 36000 | L19: ￥ | M19: =(M17+M18)*0.1 -> 18000
B20: SUB TOTAL | D20: ￥ | E20: =SUM(E15:G19) -> 880000 | H20: ￥ | I20: =SUM(I15:K19) -> 396000 | L20: ￥ | M20: =SUM(M15:O19) -> 198000
A23: ◆College Preparatory 1.5 year Course (Starting in October)
D24: On Admission | H24: September (2nd Year) | L24: GRAND TOTAL
B25: Admission Fee | D25: ￥ | E25: 50000 | L25: ￥ | M25: =SUM(A30,E30,I30) -> 1276000
B26: Examination Fee | D26: ￥ | E26: 30000
B27: Tuition | D27: ￥ | E27: ='installment plan'!E27:G27*2 -> 660000 | H27: ￥ | I27: ='installment plan'!I27:K27 -> 330000
B28: Miscellaneous Fee | D28: ￥ | E28: ='installment plan'!E28:G28*2 -> 60000 | H28: ￥ | I28: ='installment plan'!I28:K28 -> 30000
B29: Consumption Tax(10%) | D29: ￥ | E29: =(E25+E26+E27+E28)*0.1 -> 80000 | H29: ￥ | I29: =(I27+I28)*0.1 -> 36000
B30: SUB TOTAL | D30: ￥ | E30: =SUM(E25:G29) -> 880000 | H30: ￥ | I30: =SUM(I25:K29) -> 396000
A33: ◆College Preparatory 1.3 year Course (Starting in January)
D34: On Admission | H34: December | L34: GRAND TOTAL
B35: Admission Fee | D35: ￥ | E35: 50000 | L35: ￥ | M35: =SUM(A40,E40,I40) -> 1078000
B36: Examination Fee | D36: ￥ | E36: 30000
B37: Tuition | D37: ￥ | E37: ='installment plan'!E37:G37*2 -> 660000 | H37: ￥ | I37: =E37/4 -> 165000
B38: Miscellaneous Fee | D38: ￥ | E38: ='installment plan'!E38:G38*2 -> 60000 | H38: ￥ | I38: =E38/4 -> 15000
B39: Consumption Tax(10%) | D39: ￥ | E39: =(E35+E36+E37+E38)*0.1 -> 80000 | H39: ￥ | I39: =(I37+I38)*0.1 -> 18000
B40: SUB TOTAL | D40: ￥ | E40: =SUM(E35:G39) -> 880000 | H40: ￥ | I40: =SUM(I35:K39) -> 198000
I42: ASIAN ACADEMY
Q45: 2022.9.1
A46: THE INITIAL PAYMENT
B49: SCHOOL FEE | D49: JPY 800,000
B50: CONSUMPTION TAX(10%) | D50: JPY 80,000
B51: INSURANCE FOR ACCIDENT | D51: JPY 10,000 | H51: ( 1 Year)
...

Sheet installment plan
A1: EXPENSES
Q2: 2022.9.1
A3: ◆College Preparatory 2 year Course (Starting in April)
D4: On Admission | H4: September | L4: March (2nd Year) | P4: September (2nd Year)
B5: Admission Fee | D5: ￥ | E5: 50000
B6: Examination Fee | D6: ￥ | E6: 30000
B7: Tuition | D7: ￥ | E7: 330000 | H7: ￥ | I7: 330000 | L7: ￥ | M7: 330000 | P7: ￥ | Q7: 330000
B8: Miscellaneous Fee | D8: ￥ | E8: 30000 | H8: ￥ | I8: 30000 | L8: ￥ | M8: 30000 | P8: ￥ | Q8: 30000
B9: Consumption Tax(10%) | D9: ￥ | E9: =(E5+E6+E7+E8)*0.1 -> 44000 | H9: ￥ | I9: =(I7+I8)*0.1 -> 36000 | L9: ￥ | M9: =(M7+M8)*0.1 -> 36000 | P9: ￥ | Q9: =(Q7+Q8)*0.1 -> 36000
B10: SUB TOTAL | D10: ￥ | E10: =SUM(E5:G9) -> 484000 | H10: ￥ | I10: =SUM(I5:K9) -> 396000 | L10: ￥ | M10: =SUM(M5:O9) -> 396000 | P10: ￥ | Q10: =SUM(Q5:S9) -> 396000
A13: ◆College Preparatory 1.9 year Course (Starting in July)
D14: On Admission | H14: December | L14: June (2nd Year) | P14: December (2nd Year)
B15: Admission Fee | D15: ￥ | E15: 50000
B16: Examination Fee | D16: ￥ | E16: 30000
B17: Tuition | D17: ￥ | E17: 330000 | H17: ￥ | I17: 330000 | L17: ￥ | M17: 330000 | P17: ￥ | Q17: =M17/2 -> 165000
B18: Miscellaneous Fee | D18: ￥ | E18: 30000 | H18: ￥ | I18: 30000 | L18: ￥ | M18: 30000 | P18: ￥ | Q18: =M18/2 -> 15000
B19: Consumption Tax(10%) | D19: ￥ | E19: =(E15+E16+E17+E18)*0.1 -> 44000 | H19: ￥ | I19: =(I17+I18)*0.1 -> 36000 | L19: ￥ | M19: =(M17+M18)*0.1 -> 36000 | P19: ￥ | Q19: =(Q17+Q18)*0.1 -> 18000
B20: SUB TOTAL | D20: ￥ | E20: =SUM(E15:G19) -> 484000 | H20: ￥ | I20: =SUM(I15:K19) -> 396000 | L20: ￥ | M20: =SUM(M15:O19) -> 396000 | P20: ￥ | Q20: =SUM(Q15:S19) -> 198000
A23: ◆College Preparatory 1.5 year Course (Starting in October)
D24: On Admission | H24: March | L24: September (2nd Year)
B25: Admission Fee | D25: ￥ | E25: 50000
B26: Examination Fee | D26: ￥ | E26: 30000
B27: Tuition | D27: ￥ | E27: 330000 | H27: ￥ | I27: 330000 | L27: ￥ | M27: 330000
B28: Miscellaneous Fee | D28: ￥ | E28: 30000 | H28: ￥ | I28: 30000 | L28: ￥ | M28: 30000
B29: Consumption Tax(10%) | D29: ￥ | E29: =(E25+E26+E27+E28)*0.1 -> 44000 | H29: ￥ | I29: =(I27+I28)*0.1 -> 36000 | L29: ￥ | M29: =(M27+M28)*0.1 -> 36000
B30: SUB TOTAL | D30: ￥ | E30: =SUM(E25:G29) -> 484000 | H30: ￥ | I30: =SUM(I25:K29) -> 396000 | L30: ￥ | M30: =SUM(M25:O29) -> 396000
A33: ◆College Preparatory 1.3 year Course (Starting in January)
D34: On Admission | H34: June | L34: December
B35: Admission Fee | D35: ￥ | E35: 50000
B36: Examination Fee | D36: ￥ | E36: 30000
B37: Tuition | D37: ￥ | E37: 330000 | H37: ￥ | I37: 330000 | L37: ￥ | M37: =I37/2 -> 165000
B38: Miscellaneous Fee | D38: ￥ | E38: 30000 | H38: ￥ | I38: 30000 | L38: ￥ | M38: =I38/2 -> 15000
B39: Consumption Tax(10%) | D39: ￥ | E39: =(E35+E36+E37+E38)*0.1 -> 44000 | H39: ￥ | I39: =(I37+I38)*0.1 -> 36000 | L39: ￥ | M39: =(M37+M38)*0.1 -> 18000
B40: SUB TOTAL | D40: ￥ | E40: =SUM(E35:G39) -> 484000 | H40: ￥ | I40: =SUM(I35:K39) -> 396000 | L40: ￥ | M40: =SUM(M35:O39) -> 198000
I42: ASIAN ACADEMY
Q45: 2022.9.1
A46: THE INITIAL PAYMENT
B49: SCHOOL FEE | D49: JPY 440,000
B50: CONSUMPTION TAX(10%) | D50: JPY 44,000
B51: INSURANCE FOR ACCIDENT | D51: JPY 10,000 | H51: ( 1 Year)
...

Sheet app. form
A1: REQUIRED DOCUMENTS | G1: APPLICATION FORM | O1: ASIAN ACADEMY, KOBE
A3: NAME | C3: SURNAME | J3: GIVEN NAME
C4: PARAG | J4: ARIFUL HOQUE
A5: NATIONALITY | F5: DATE OF BIRTH | O5: GENDER | Q5: PHOTO
A6: BANGLADESHI | F6: (Y) | G6: 2002 | I6: /(M) | J6: 10 | L6: /(D) | M6: 25 | O6: MALE FEMALE
A7: HOME COUNTRY | C7: REGISTERED ADDRESS | Q7: 4cm × 3cm
C8: METONGHER, UTTAR PARA, BANGORA BAZAR, PANDUGHAR-3543, CUMILLA
C9: ACTUAL ADDRESS
C10: same as above /
C11: HOME PHONE NUMBER / NONE | K11: MOBILE PHONE NUMBER
C12: +8801522126395 | K12: +8801762971934
A14: SPONSOR AND FAMILY (Describe up to the second degree of kinship including "separated" or "divorced".
A15: NAME | D15: RELATION | F15: DATE OF BIRTH | I15: ADDRESS | Q15: OCCUPATION/REMARK
I16: REGISTERED ADDRESS
I17: ACTUAL ADDRESS / SAME AS ABOVE
I18: REGISTERED ADDRESS
I19: ACTUAL ADDRESS / SAME AS ABOVE
I20: REGISTERED ADDRESS
I21: ACTUAL ADDRESS / SAME AS ABOVE
I22: REGISTERED ADDRESS
I23: ACTUAL ADDRESS / SAME AS ABOVE
I24: REGISTERED ADDRESS
I25: ACTUAL ADDRESS / SAME AS ABOVE
A27: ACADEMIC RECORD (FROM PRIMARY SCHOOL TO THE FINAL RECORD)
C28: NAME OF SHOOL & ADDRESS | L28: DATE OF ADMISSION | O28: DATE OF GRADUATION | R28: PERIOD
A29: NAME | C29: KURAIBARI PRIMARY SCHOOL | L29: (Y) 2008 /(M) 1 /(D)1 | O29: (Y) 2013 /(M) 12 /(D)30 | R29: 5 YEARS
A30: ADDRESS | C30: KURAIBARI, BANGORA BAZAR, PANDUGHAR-3543, CUMILLA
A31: NAME | C31: METONGHER B. R. I. M. HIGH SCHOOL | L31: (Y) 2014 /(M)1 /(D)1 | O31: (Y) 2019/(M) 5 /(D)6 | R31: 5 YEARS
A32: ADDRESS | C32: METONGHER, BANGORA BAZAR, CUMILLA
A33: NAME | C33: VASHANTEK GOVT. COLLEGE | L33: (Y) 2024 /(M)1 /(D)1 | O33: (Y) 2025 /(M) 10 /(D)16 | R33: 2 YEARS
A34: ADDRESS | C34: VASHANTEK ROAD, DHAKA
A35: NAME | L35: (Y) /(M) /(D) | O35: (Y) /(M) /(D) | R35: YEARS
A36: ADDRESS
A38: JOB CAREER | E38: NONE
A39: NAME | P39: TYPE OF JOB | R39: PERIOD
L40: (Y) /(M) /(D) ～ | R40: YEARS
A41: ADDRESS
L42: (Y) /(M) /(D)
A44: RECORD OF JAPANESE LANGUAGE LEARNING
A45: NAME | C45: AN NUR JAPANESE LANGUAGE SCHOOL | P45: PERIOD | R45: TOTAL HOURS
...

Sheet sponsor
A1: REQUIRED DOCUMENTS | Q1: アジア学院 ASIAN ACADEMY
A2: STATEMENT OF SPONSORSHIP
A4: TO THE MINISTER OF JUSTICE OF JAPAN
B6: NATIONALITY | M6: DATE OF BIRTH | Q6: (Y) /(M) /(D)
B7: BANGLADESHI | Q7: 2002 10 25
B8: APPLICANT'S NAME | F8: ARIFUL HOQUE PARAG | T8: MALE / FEMALE
A10: I have become the financial sponsor of the person above concerning his/her all the expense
A11: while staying in Japan. I explain the reason of sponsoring the person above and its method.
A13: 1 THE REASON OF SPONSORING(Describe the reason and the relation to the applicant in detail.)
A14: I, MANSURA BEGUM, am sponsoring the applicant because he is my son. I would like to support his
A15: higher education in Japan. During his stay in Japan, I will bear his tuition fees and living expenses.
A16: I have sufficient financial ability to support him throughout his study period.
A18: 2 THE METHOD OF SPONSORSHIP
A19: I declare I will financially support the person above concerning his/her all the expense while staying in Japan
A20: as below. I also submit the certificate of remittance or the copy of his/her bank book to prove my sponsorship.
B22: -1 | C22: TUITION | J22: \ | L22: 800000
B23: -2 | C23: MONTHLY LIVING EXPENSE | J23: \
B24: -3 | C24: METHOD | F24: (Please describe how the applicant receive the expense from you in detail.)
Q29: (Y)2026 /(M) 03 /(D)11
A30: < SPONSOR > | E30: ADDRESS | H30: METONGHER, UTTAR PARA, BANGORA BAZAR, PANDUGHAR-3543, CUMILLA
E31: PHONE NUMBER | I31: 8801522126395
E32: NAME & SIGNATURE OF SPONSOR | L32: MST SHAJEDA KHATUN
E33: RELATION TO THE APPLICANT | L33: MOTHER
